Workbook

Sheet Resumen
A1: Auditoría SEO de textos – Technofood (tienda Shopify)
A2: Fecha: 15 de octubre de 2026. Fuente: datos de la tienda en Shopify (productos, colecciones). No incluye textos del tema (home, Nosotros, H1) porque la tienda tiene contraseña.
A4: Indicador | B4: Valor | C4: Cómo se calcula / observación
A5: Productos activos analizados | B5: =COUNTA(Productos!A2:A243) -> 242 | C5: Todos los productos activos de la tienda.
A6: Productos con SEO title y meta description hoy | B6: 0 | C6: Observación en Shopify: 0 de los primeros 100 productos revisados tenía SEO title o meta description propios. Se asume igual para el resto.
A7: Colecciones analizadas | B7: =COUNTA(Colecciones!A2:A119) -> 118 | C7: Total de colecciones leídas.
A8: Colecciones con descripción o imagen hoy | B8: 0 | C8: Observación: ninguna tiene imagen ni SEO propio; solo 'Avícola' tiene descripción y es texto de prueba.
A9: Títulos de producto a corregir (mayúsculas/marca) | B9: =SUMPRODUCT(--NOT(EXACT(Productos!C2:C243,Productos!D2:D243))) -> 225 | C9: Comparación exacta entre título actual y sugerido.
A10: SEO titles propuestos dentro de 60 caracteres | B10: =COUNTIF(Productos!G2:G243,"OK") -> 242 | C10: De los productos; los 'Largo' requieren edición manual.
A11: Meta descriptions propuestas entre 120 y 155 caracteres | B11: =COUNTIF(Productos!J2:J243,"OK") -> 242 | C11: Las 'Corta' o 'Larga' requieren edición manual.
A12: Colecciones vacías (0 productos) | B12: =COUNTIF(Colecciones!C2:C119,0) -> 8 | C12: Ocultar de la navegación y aplicar noindex.
A13: Colecciones con 1 producto | B13: =COUNTIF(Colecciones!C2:C119,1) -> 19 | C13: Candidatas a fusionar o noindex (las de marca se mantienen).
A14: Colecciones con acción 'Fusionar' o 'Revisar' | B14: =COUNTIF(Colecciones!F2:F119,"Fusionar*")+COUNTIF(Colecciones!F2:F119,"Revisar*") -> 25 | C14: Ver columna 'Acción recomendada'.
A15: Productos sin imagen | B15: 1 | C15: Observación: 'Sierra para Desposte EFA 86' no tiene imágenes cargadas.
A17: Método y supuestos
A18: • Título sugerido: iniciales en mayúscula (según lo pedido), siglas y modelos en mayúscula, y marca agregada cuando el título no la tenía.
A19: • SEO title: '[Título sugerido] | Technofood Colombia' (si pasa de 60 caracteres se acorta a '| Technofood' o se deja solo el título).
A20: • Meta description: plantilla generada a partir del título y la marca (no de la descripción del producto). Es una base: personalizar al menos los productos destacados.
A21: • Los textos de categorías no inventan cifras ni especificaciones; las marcas citadas salen de las colecciones y de los PDF corporativos de marcas por proceso e industria.
A22: • Las palabras clave son propuestas cualitativas, sin volumen de búsqueda (no hay acceso a Search Console ni a Semrush).
A23: • Celdas con fondo azul claro = propuestas editables por el equipo.
A25: Cómo aplicarlo
A26: 1. Productos: revise la hoja 'Productos' y corrija lo marcado 'Largo/Corta' y las notas. Luego exporte la hoja 'Importar a Shopify' como CSV (UTF-8) e impórtela en Shopify (Productos → Importar). Haga primero una prueba con 5 productos y un respaldo de la exportación actual.
A27: 2. Ojo: la importación cambia el Título del producto; el handle no cambia (no hay que crear redirecciones).
A28: 3. Colecciones: Shopify no importa SEO de colecciones por CSV. Se editan una por una (SEO title, meta, imagen y descripción) o con ayuda de Claude Code o una app.
A29: 4. Fusionar o redirigir colecciones: cree redirecciones 301 en Contenido → Navegación → Redirecciones de URL antes de borrar cualquier colección.
... A38: Importar a Shopify: columnas Handle, Title, SEO Title, SEO Description listas para CSV.

Sheet Productos
A1: Handle | B1: Marca | C1: Título actual en Shopify | D1: Título sugerido (H1) | E1: SEO title propuesto | F1: Largo SEO title | G1: Estado title (≤60) | H1: Meta description propuesta | I1: Largo meta | J1: Estado meta (120–155) | K1: Alt de imagen sugerido | L1: Notas / hallazgos
A2: horno-tipo-batch-mwb2260r-440-75 | B2: Amtek | C2: HORNO TIPO BATCH MWB2260R-440-75 | D2: Horno Tipo Batch MWB2260R-440-75 Amtek | E2: Horno Tipo Batch MWB2260R-440-75 Amtek | Technofood Colombia | F2: =LEN(E2) -> 60 | G2: =IF(F2<=60,"OK","Largo") -> OK | H2: Horno Tipo Batch MWB2260R-440-75 Amtek: equipo industrial. Distribuidor autorizado en Colombia. Solicite su cotización con un asesor de Technofood. | I2: =LEN(H2) -> 147 | J2: =IF(AND(I2>=120,I2<=155),"OK",IF(I2<120,"Corta","Larga")) -> OK | K2: Horno Tipo Batch MWB2260R-440-75 Amtek – equipo industrial para la industria de alimentos | L2: Título en mayúsculas: se pasó a iniciales en mayúscula. Se agregó la marca al título (no la tenía).
A3: agente-abrillantador-backglanz-fix-fertig-100-vegetal | B3: Boyens | C3: Agente abrillantador BackGlanz fix & fertig (100% vegetal) | D3: Agente Abrillantador BackGlanz Fix & Fertig (100% Vegetal) Boyens | E3: Agente Abrillantador BackGlanz Fix & Fertig | Boyens | F3: =LEN(E3) -> 52 | G3: =IF(F3<=60,"OK","Largo") -> OK | H3: Agente Abrillantador BackGlanz Fix & Fertig Boyens. Distribuidor autorizado en Colombia. Solicite su cotización con Technofood. | I3: =LEN(H3) -> 127 | J3: =IF(AND(I3>=120,I3<=155),"OK",IF(I3<120,"Corta","Larga")) -> OK | K3: Agente Abrillantador BackGlanz Fix & Fertig (100% Vegetal) Boyens – insumo industrial para la industria de alimentos | L3: Se agregó la marca al título (no la tenía). SEO title y meta acortados a mano (el título completo es muy largo).
A4: cortadora-cws-300 | B4: Grasselli | C4: CORTADORA CWS 300 | D4: Cortadora CWS 300 Grasselli | E4: Cortadora CWS 300 Grasselli | Technofood Colombia | F4: =LEN(E4) -> 49 | G4: =IF(F4<=60,"OK","Largo") -> OK | H4: Cortadora CWS 300 Grasselli: equipo industrial para la industria de alimentos. Distribuidor autorizado en Colombia. Solicite su cotización con Technofood. | I4: =LEN(H4) -> 154 | J4: =IF(AND(I4>=120,I4<=155),"OK",IF(I4<120,"Corta","Larga")) -> OK | K4: Cortadora CWS 300 Grasselli – equipo industrial para la industria de alimentos | L4: Título en mayúsculas: se pasó a iniciales en mayúscula. Se agregó la marca al título (no la tenía).
A5: sistema-de-temperado-amt4412r-440-2x74 | B5: Amtek | C5: SISTEMA DE TEMPERADO AMT4412R-440-2X74 | D5: Sistema de Temperado AMT4412R-440-2X74 Amtek | E5: Sistema de Temperado AMT4412R-440-2X74 Amtek | Technofood | F5: =LEN(E5) -> 57 | G5: =IF(F5<=60,"OK","Largo") -> OK | H5: Sistema de Temperado AMT4412R-440-2X74 Amtek: equipo industrial. Distribuidor autorizado en Colombia. Solicite su cotización con un asesor de Technofood. | I5: =LEN(H5) -> 153 | J5: =IF(AND(I5>=120,I5<=155),"OK",IF(I5<120,"Corta","Larga")) -> OK | K5: Sistema de Temperado AMT4412R-440-2X74 Amtek – equipo industrial para la industria de alimentos | L5: Título en mayúsculas: se pasó a iniciales en mayúscula. Se agregó la marca al título (no la tenía).
A6: sistema-de-temperado-amt4412r-440-75 | B6: Amtek | C6: SISTEMA DE TEMPERADO AMT4412R-440-75 | D6: Sistema de Temperado AMT4412R-440-75 Amtek | E6: Sistema de Temperado AMT4412R-440-75 Amtek | Technofood | F6: =LEN(E6) -> 55 | G6: =IF(F6<=60,"OK","Largo") -> OK | H6: Sistema de Temperado AMT4412R-440-75 Amtek: equipo industrial. Distribuidor autorizado en Colombia. Solicite su cotización con un asesor de Technofood. | I6: =LEN(H6) -> 151 | J6: =IF(AND(I6>=120,I6<=155),"OK",IF(I6<120,"Corta","Larga")) -> OK | K6: Sistema de Temperado AMT4412R-440-75 Amtek – equipo industrial para la industria de alimentos | L6: Título en mayúsculas: se pasó a iniciales en mayúscula. Se agregó la marca al título (no la tenía).
A7: arandela-compacta-para-suela-y-empeines-550402m | B7: AWE | C7: ARANDELA COMPACTA PARA SUELA Y EMPEINES 550402M | D7: Arandela Compacta para Suela y Empeines 550402M AWE | E7: Arandela Compacta para Suela y Empeines 550402M AWE | F7: =LEN(E7) -> 51 | G7: =IF(F7<=60,"OK","Largo") -> OK | H7: Arandela Compacta para Suela y Empeines 550402M AWE. Distribuidor autorizado en Colombia. Solicite su cotización con Technofood. | I7: =LEN(H7) -> 128 | J7: =IF(AND(I7>=120,I7<=155),"OK",IF(I7<120,"Corta","Larga")) -> OK | K7: Arandela Compacta para Suela y Empeines 550402M AWE – equipo industrial para la industria de alimentos | L7: Título en mayúsculas: se pasó a iniciales en mayúscula. Se agregó la marca al título (no la tenía). Verificar traducción: 'arandela' es una pieza metálica; el equipo es una lavadora de suelas y empeines.
A8: dispositivo-movil-de-desinfeccion-de-manos-spraybox-551801-nm | B8: AWE | C8: DISPOSITIVO MÓVIL DE DESINFECCIÓN DE MANOS SPRAYBOX 551801 NM | D8: Dispositivo Móvil de Desinfección de Manos Spraybox 551801 NM AWE | E8: Desinfección de Manos Spraybox 551801 NM | AWE | F8: =LEN(E8) -> 46 | G8: =IF(F8<=60,"OK","Largo") -> OK | H8: Dispositivo de Desinfección de Manos Spraybox 551801 NM AWE. Distribuidor autorizado en Colombia. Solicite su cotización con Technofood. | I8: =LEN(H8) -> 136 | J8: =IF(AND(I8>=120,I8<=155),"OK",IF(I8<120,"Corta","Larga")) -> OK | K8: Dispositivo Móvil de Desinfección de Manos Spraybox 551801 NM AWE – equipo industrial para la industria de alimentos | L8: Título en mayúsculas: se pasó a iniciales en mayúscula. Se agregó la marca al título (no la tenía). SEO title y meta acortados a mano (el título completo es muy largo).
A9: dispositivo-para-lavado-y-desinfeccion-de-manos-551301 | B9: AWE | C9: DISPOSITIVO PARA LAVADO Y DESINFECCIÓN DE MANOS 551301 | D9: Dispositivo para Lavado y Desinfección de Manos 551301 AWE | E9: Dispositivo para Lavado y Desinfección de Manos 551301 AWE | F9: =LEN(E9) -> 58 | G9: =IF(F9<=60,"OK","Largo") -> OK | H9: Dispositivo para Lavado y Desinfección de Manos 551301 AWE. Distribuidor autorizado en Colombia. Solicite su cotización con Technofood. | I9: =LEN(H9) -> 135 | J9: =IF(AND(I9>=120,I9<=155),"OK",IF(I9<120,"Corta","Larga")) -> OK | K9: Dispositivo para Lavado y Desinfección de Manos 551301 AWE – equipo industrial para la industria de alimentos | L9: Título en mayúsculas: se pasó a iniciales en mayúscula. Se agregó la marca al título (no la tenía).
A10: estacion-de-acceso-para-higiene-de-manos-cleangate-551404 | B10: AWE | C10: ESTACIÓN DE ACCESO PARA HIGIENE DE MANOS CLEANGATE 551404 | D10: Estación de Acceso para Higiene de Manos Cleangate 551404 AWE | E10: Estación Higiene de Manos Cleangate 551404 | AWE | F10: =LEN(E10) -> 48 | G10: =IF(F10<=60,"OK","Largo") -> OK | H10: Estación de Higiene de Manos Cleangate 551404 AWE. Distribuidor autorizado en Colombia. Solicite su cotización con Technofood. | I10: =LEN(H10) -> 126 | J10: =IF(AND(I10>=120,I10<=155),"OK",IF(I10<120,"Corta","Larga")) -> OK | K10: Estación de Acceso para Higiene de Manos Cleangate 551404 AWE – equipo industrial para la industria de alimentos | L10: Título en mayúsculas: se pasó a iniciales en mayúscula. Se agregó la marca al título (no la tenía). SEO title y meta acortados a mano (el título completo es muy largo).
A11: lavabo-higienico-con-secador-de-manos-tip-531201 | B11: AWE | C11: LAVABO HIGIÉNICO CON SECADOR DE MANOS TIP 531201 | D11: Lavabo Higiénico con Secador de Manos TIP 531201 AWE | E11: Lavabo Higiénico con Secador de Manos TIP 531201 AWE | F11: =LEN(E11) -> 52 | G11: =IF(F11<=60,"OK","Largo") -> OK | H11: Lavabo Higiénico con Secador de Manos TIP 531201 AWE. Distribuidor autorizado en Colombia. Solicite su cotización con Technofood. | I11: =LEN(H11) -> 129 | J11: =IF(AND(I11>=120,I11<=155),"OK",IF(I11<120,"Corta","Larga")) -> OK | K11: Lavabo Higiénico con Secador de Manos TIP 531201 AWE – equipo industrial para la industria de alimentos | L11: Título en mayúsculas: se pasó a iniciales en mayúscula. Se agregó la marca al título (no la tenía).
A12: lavabo-higienico-mural-kleanox-531001b | B12: AWE | C12: LAVABO HIGIÉNICO MURAL KLEANOX 531001B | D12: Lavabo Higiénico Mural Kleanox 531001B AWE | E12: Lavabo Higiénico Mural Kleanox 531001B AWE | Technofood | F12: =LEN(E12) -> 55 | G12: =IF(F12<=60,"OK","Largo") -> OK | H12: Lavabo Higiénico Mural Kleanox 531001B AWE: equipo industrial. Distribuidor autorizado en Colombia. Solicite su cotización con un asesor de Technofood. | I12: =LEN(H12) -> 151 | J12: =IF(AND(I12>=120,I12<=155),"OK",IF(I12<120,"Corta","Larga")) -> OK | K12: Lavabo Higiénico Mural Kleanox 531001B AWE – equipo industrial para la industria de alimentos | L12: Título en mayúsculas: se pasó a iniciales en mayúscula. Se agregó la marca al título (no la tenía).
A13: lavadora-de-calzado-manual-scrubo-pro-550102 | B13: AWE | C13: LAVADORA DE CALZADO MANUAL SCRUBO PRO 550102 | D13: Lavadora de Calzado Manual Scrubo Pro 550102 AWE | E13: Lavadora de Calzado Manual Scrubo Pro 550102 AWE | F13: =LEN(E13) -> 48 | G13: =IF(F13<=60,"OK","Largo") -> OK | H13: Lavadora de Calzado Manual Scrubo Pro 550102 AWE. Distribuidor autorizado en Colombia. Solicite su cotización con Technofood. | I13: =LEN(H13) -> 125 | J13: =IF(AND(I13>=120,I13<=155),"OK",IF(I13<120,"Corta","Larga")) -> OK | K13: Lavadora de Calzado Manual Scrubo Pro 550102 AWE – equipo industrial para la industria de alimentos | L13: Título en mayúsculas: se pasó a iniciales en mayúscula. Se agregó la marca al título (no la tenía).
... A105: sistema-de-dosificacion-cedev-4150 | B105: Velec | C105: SISTEMA DE DOSIFICACIÓN CEDEV 4150 | D105: Sistema de Dosificación Cedev 4150 Velec | E105: Sistema de Dosificación Cedev 4150 Velec | Technofood | F105: =LEN(E105) -> 53 | G105: =IF(F105<=60,"OK","Largo") -> OK | H105: Sistema de Dosificación Cedev 4150 Velec: equipo industrial. Distribuidor autorizado en Colombia. Solicite su cotización con un asesor de Technofood. | I105: =LEN(H105) -> 149 | J105: =IF(AND(I105>=120,I105<=155),"OK",IF(I105<120,"Corta","Larga")) -> OK | K105: Sistema de Dosificación Cedev 4150 Velec – equipo industrial para la industria de alimentos | L105: Título en mayúsculas: se pasó a iniciales en mayúscula. Se agregó la marca al título (no la tenía).
A106: carro-cutter-awe | B106: AWE | C106: Carro cutter Awe | D106: Carro Cutter AWE | E106: Carro Cutter AWE | Technofood Colombia | F106: =LEN(E106) -> 38 | G106: =IF(F106<=60,"OK","Largo") -> OK | H106: Carro Cutter AWE: insumo industrial para la industria de alimentos. Distribuidor autorizado en Colombia. Solicite su cotización con Technofood. | I106: =LEN(H106) -> 143 | J106: =IF(AND(I106>=120,I106<=155),"OK",IF(I106<120,"Corta","Larga")) -> OK | K106: Carro Cutter AWE – insumo industrial para la industria de alimentos
A107: dedos-de-goma-desplumadores-baader | B107: Baader | C107: Dedos de goma desplumadores Baader | D107: Dedos de Goma Desplumadores Baader | E107: Dedos de Goma Desplumadores Baader | Technofood Colombia | F107: =LEN(E107) -> 56 | G107: =IF(F107<=60,"OK","Largo") -> OK | H107: Dedos de Goma Desplumadores Baader: insumo industrial. Distribuidor autorizado en Colombia. Solicite su cotización con un asesor de Technofood. | I107: =LEN(H107) -> 143 | J107: =IF(AND(I107>=120,I107<=155),"OK",IF(I107<120,"Corta","Larga")) -> OK | K107: Dedos de Goma Desplumadores Baader – insumo industrial para la industria de alimentos
A108: pig-plug-efa | B108: EFA | C108: Pig Plug Efa | D108: Pig Plug EFA | E108: Pig Plug EFA | Technofood Colombia | F108: =LEN(E108) -> 34 | G108: =IF(F108<=60,"OK","Largo") -> OK | H108: Pig Plug EFA: insumo industrial para la industria de alimentos. Distribuidor autorizado en Colombia. Solicite su cotización con Technofood. | I108: =LEN(H108) -> 139 | J108: =IF(AND(I108>=120,I108<=155),"OK",IF(I108<120,"Corta","Larga")) -> OK | K108: Pig Plug EFA – insumo industrial para la industria de alimentos
A109: rollos-de-papel-para-hamburguesa-gaser | B109: Gaser | C109: Rollos de papel para hamburguesa Gaser | D109: Rollos de Papel para Hamburguesa Gaser | E109: Rollos de Papel para Hamburguesa Gaser | Technofood Colombia | F109: =LEN(E109) -> 60 | G109: =IF(F109<=60,"OK","Largo") -> OK | H109: Rollos de Papel para Hamburguesa Gaser: insumo industrial. Distribuidor autorizado en Colombia. Solicite su cotización con un asesor de Technofood. | I109: =LEN(H109) -> 147 | J109: =IF(AND(I109>=120,I109<=155),"OK",IF(I109<120,"Corta","Larga")) -> OK | K109: Rollos de Papel para Hamburguesa Gaser – insumo industrial para la industria de alimentos
A110: cartucho-de-tinta-solvente-hp-975-para-codificador | B110: HP | C110: Cartucho de tinta solvente HP 975 para codificador | D110: Cartucho de Tinta Solvente HP 975 para Codificador | E110: Cartucho de Tinta Solvente HP 975 para Codificador | F110: =LEN(E110) -> 50 | G110: =IF(F110<=60,"OK","Largo") -> OK | H110: Cartucho de Tinta Solvente HP 975 para Codificador. Distribuidor autorizado en Colombia. Solicite su cotización con Technofood. | I110: =LEN(H110) -> 127 | J110: =IF(AND(I110>=120,I110<=155),"OK",IF(I110<120,"Corta","Larga")) -> OK | K110: Cartucho de Tinta Solvente HP 975 para Codificador – insumo industrial para la industria de alimentos
A111: clips-de-aluminio-international-clip | B111: International Clip | C111: Clips de aluminio International Clip | D111: Clips de Aluminio International Clip | E111: Clips de Aluminio International Clip | Technofood Colombia | F111: =LEN(E111) -> 58 | G111: =IF(F111<=60,"OK","Largo") -> OK | H111: Clips de Aluminio International Clip: insumo industrial. Distribuidor autorizado en Colombia. Solicite su cotización con un asesor de Technofood. | I111: =LEN(H111) -> 145 | J111: =IF(AND(I111>=120,I111<=155),"OK",IF(I111<120,"Corta","Larga")) -> OK | K111: Clips de Aluminio International Clip – insumo industrial para la industria de alimentos
A112: lazos-para-salchichon-international-clip-gs-25 | B112: International Clip | C112: Lazos para salchichón International Clip GS 25 | D112: Lazos para Salchichón International Clip GS 25 | E112: Lazos para Salchichón International Clip GS 25 | Technofood | F112: =LEN(E112) -> 59 | G112: =IF(F112<=60,"OK","Largo") -> OK | H112: Lazos para Salchichón International Clip GS 25: insumo industrial. Distribuidor autorizado en Colombia. Solicite su cotización con un asesor de Technofood. | I112: =LEN(H112) -> 155 | J112: =IF(AND(I112>=120,I112<=155),"OK",IF(I112<120,"Corta","Larga")) -> OK | K112: Lazos para Salchichón International Clip GS 25 – insumo industrial para la industria de alimentos
A113: rascador-taesa-ueb-1 | B113: Taesa | C113: Rascador Taesa UEB-1 | D113: Rascador Taesa UEB-1 | E113: Rascador Taesa UEB-1 | Technofood Colombia | F113: =LEN(E113) -> 42 | G113: =IF(F113<=60,"OK","Largo") -> OK | H113: Rascador Taesa UEB-1: insumo industrial para la industria de alimentos. Distribuidor autorizado en Colombia. Solicite su cotización con Technofood. | I113: =LEN(H113) -> 147 | J113: =IF(AND(I113>=120,I113<=155),"OK",IF(I113<120,"Corta","Larga")) -> OK | K113: Rascador Taesa UEB-1 – insumo industrial para la industria de alimentos
A114: agente-desmoldante-pco-i-10-litros | B114: Boyens | C114: Agente desmoldante PCO-I 10 litros | D114: Agente Desmoldante PCO-I 10 Litros Boyens | E114: Agente Desmoldante PCO-I 10 Litros Boyens | Technofood | F114: =LEN(E114) -> 54 | G114: =IF(F114<=60,"OK","Largo") -> OK | H114: Agente Desmoldante PCO-I 10 Litros Boyens: insumo industrial. Distribuidor autorizado en Colombia. Solicite su cotización con un asesor de Technofood. | I114: =LEN(H114) -> 150 | J114: =IF(AND(I114>=120,I114<=155),"OK",IF(I114<120,"Corta","Larga")) -> OK | K114: Agente Desmoldante PCO-I 10 Litros Boyens – insumo industrial para la industria de alimentos | L114: Se agregó la marca al título (no la tenía).
A115: agente-desmoldante-trennspray-600-ml | B115: Boyens | C115: Agente desmoldante Trennspray 600 ml | D115: Agente Desmoldante Trennspray 600 Ml Boyens | E115: Agente Desmoldante Trennspray 600 Ml Boyens | Technofood | F115: =LEN(E115) -> 56 | G115: =IF(F115<=60,"OK","Largo") -> OK | H115: Agente Desmoldante Trennspray 600 Ml Boyens: insumo industrial. Distribuidor autorizado en Colombia. Solicite su cotización con un asesor de Technofood. | I115: =LEN(H115) -> 152 | J115: =IF(AND(I115>=120,I115<=155),"OK",IF(I115<120,"Corta","Larga")) -> OK | K115: Agente Desmoldante Trennspray 600 Ml Boyens – insumo industrial para la industria de alimentos | L115: Se agregó la marca al título (no la tenía).
A116: pulverizador-manual-spruhboy-04s | B116: Boyens | C116: Pulverizador manual Sprühboy 04S | D116: Pulverizador Manual Sprühboy 04S Boyens | E116: Pulverizador Manual Sprühboy 04S Boyens | Technofood | F116: =LEN(E116) -> 52 | G116: =IF(F116<=60,"OK","Largo") -> OK | H116: Pulverizador Manual Sprühboy 04S Boyens: insumo industrial. Distribuidor autorizado en Colombia. Solicite su cotización con un asesor de Technofood. | I116: =LEN(H116) -> 148 | J116: =IF(AND(I116>=120,I116<=155),"OK",IF(I116<120,"Corta","Larga")) -> OK | K116: Pulverizador Manual Sprühboy 04S Boyens – insumo industrial para la industria de alimentos | L116: Se agregó la marca al título (no la tenía).
A117: pulverizador-manual-spruhboy-08s | B117: Boyens | C117: Pulverizador manual Sprühboy 08S | D117: Pulverizador Manual Sprühboy 08S Boyens | E117: Pulverizador Manual Sprühboy 08S Boyens | Technofood | F117: =LEN(E117) -> 52 | G117: =IF(F117<=60,"OK","Largo") -> OK | H117: Pulverizador Manual Sprühboy 08S Boyens: insumo industrial. Distribuidor autorizado en Colombia. Solicite su cotización con un asesor de Technofood. | I117: =LEN(H117) -> 148 | J117: =IF(AND(I117>=120,I117<=155),"OK",IF(I117<120,"Corta","Larga")) -> OK | K117: Pulverizador Manual Sprühboy 08S Boyens – insumo industrial para la industria de alimentos | L117: Se agregó la marca al título (no la tenía).
A118: pulverizador-manual-spruhboy-14s | B118: Boyens | C118: Pulverizador manual Sprühboy 14S | D118: Pulverizador Manual Sprühboy 14S Boyens | E118: Pulverizador Manual Sprühboy 14S Boyens | Technofood | F118: =LEN(E118) -> 52 | G118: =IF(F118<=60,"OK","Largo") -> OK | H118: Pulverizador Manual Sprühboy 14S Boyens: insumo industrial. Distribuidor autorizado en Colombia. Solicite su cotización con un asesor de Technofood. | I118: =LEN(H118) -> 148 | J118: =IF(AND(I118>=120,I118<=155),"OK",IF(I118<120,"Corta","Larga")) -> OK | K118: Pulverizador Manual Sprühboy 14S Boyens – insumo industrial para la industria de alimentos | L118: Se agregó la marca al título (no la tenía).
A119: atadora-de-bolsas-fpa-10-romms | B119: Romms | C119: Atadora de bolsas FPA-10 Romms | D119: Atadora de Bolsas FPA-10 Romms | E119: Atadora de Bolsas FPA-10 Romms | Technofood Colombia | F119: =LEN(E119) -> 52 | G119: =IF(F119<=60,"OK","Largo") -> OK | H119: Atadora de Bolsas FPA-10 Romms: equipo industrial. Distribuidor autorizado en Colombia. Solicite su cotización con un asesor de Technofood. | I119: =LEN(H119) -> 139 | J119: =IF(AND(I119>=120,I119<=155),"OK",IF(I119<120,"Corta","Larga")) -> OK | K119: Atadora de Bolsas FPA-10 Romms – equipo industrial para la industria de alimentos
A120: bandeja-de-aluminio-lisa-para-hornear-technofood | B120: Technofood | C120: Bandeja de aluminio lisa para hornear Technofood | D120: Bandeja de Aluminio Lisa para Hornear Technofood | E120: Bandeja de Aluminio Lisa para Hornear Technofood | F120: =LEN(E120) -> 48 | G120: =IF(F120<=60,"OK","Largo") -> OK | H120: Bandeja de Aluminio Lisa para Hornear Technofood. Distribuidor autorizado en Colombia. Solicite su cotización con Technofood. | I120: =LEN(H120) -> 125 | J120: =IF(AND(I120>=120,I120<=155),"OK",IF(I120<120,"Corta","Larga")) -> OK | K120: Bandeja de Aluminio Lisa para Hornear Technofood – insumo industrial para la industria de alimentos
A121: bandeja-de-aluminio-perforada-para-hornear-technofood | B121: Technofood | C121: Bandeja de aluminio perforada para hornear Technofood | D121: Bandeja de Aluminio Perforada para Hornear Technofood | E121: Bandeja de Aluminio Perforada para Hornear Technofood | F121: =LEN(E121) -> 53 | G121: =IF(F121<=60,"OK","Largo") -> OK | H121: Bandeja de Aluminio Perforada para Hornear Technofood. Distribuidor autorizado en Colombia. Solicite su cotización con Technofood. | I121: =LEN(H121) -> 130 | J121: =IF(AND(I121>=120,I121<=155),"OK",IF(I121<120,"Corta","Larga")) -> OK | K121: Bandeja de Aluminio Perforada para Hornear Technofood – insumo industrial para la industria de alimentos
A122: carretes-rollos-de-atar-technofood | B122: Technofood | C122: Carretes (rollos de atar) Technofood | D122: Carretes (Rollos de Atar) Technofood | E122: Carretes (Rollos de Atar) Technofood | Technofood Colombia | F122: =LEN(E122) -> 58 | G122: =IF(F122<=60,"OK","Largo") -> OK | H122: Carretes (Rollos de Atar) Technofood: insumo industrial. Distribuidor autorizado en Colombia. Solicite su cotización con un asesor de Technofood. | I122: =LEN(H122) -> 145 | J122: =IF(AND(I122>=120,I122<=155),"OK",IF(I122<120,"Corta","Larga")) -> OK | K122: Carretes (Rollos de Atar) Technofood – insumo industrial para la industria de alimentos
A123: cuchillas-para-rebanar-pan-technofood | B123: Technofood | C123: Cuchillas para rebanar pan Technofood | D123: Cuchillas para Rebanar Pan Technofood | E123: Cuchillas para Rebanar Pan Technofood | Technofood Colombia | F123: =LEN(E123) -> 59 | G123: =IF(F123<=60,"OK","Largo") -> OK | H123: Cuchillas para Rebanar Pan Technofood: insumo industrial. Distribuidor autorizado en Colombia. Solicite su cotización con un asesor de Technofood. | I123: =LEN(H123) -> 146 | J123: =IF(AND(I123>=120,I123<=155),"OK",IF(I123<120,"Corta","Larga")) -> OK | K123: Cuchillas para Rebanar Pan Technofood – insumo industrial para la industria de alimentos
A124: maquina-de-croissants-baby-2800-alba | B124: Alba | C124: Máquina de croissants Baby 2800 Alba | D124: Máquina de Croissants Baby 2800 Alba | E124: Máquina de Croissants Baby 2800 Alba | Technofood Colombia | F124: =LEN(E124) -> 58 | G124: =IF(F124<=60,"OK","Largo") -> OK | H124: Máquina de Croissants Baby 2800 Alba: equipo industrial. Distribuidor autorizado en Colombia. Solicite su cotización con un asesor de Technofood. | I124: =LEN(H124) -> 145 | J124: =IF(AND(I124>=120,I124<=155),"OK",IF(I124<120,"Corta","Larga")) -> OK | K124: Máquina de Croissants Baby 2800 Alba – equipo industrial para la industria de alimentos
A125: maquina-de-croissants-vacios-croistar-5000-alba | B125: Alba | C125: Máquina de croissants vacíos Croistar 5000 Alba | D125: Máquina de Croissants Vacíos Croistar 5000 Alba | E125: Máquina de Croissants Vacíos Croistar 5000 Alba | Technofood | F125: =LEN(E125) -> 60 | G125: =IF(F125<=60,"OK","Largo") -> OK | H125: Máquina de Croissants Vacíos Croistar 5000 Alba. Distribuidor autorizado en Colombia. Solicite su cotización con Technofood. | I125: =LEN(H125) -> 124 | J125: =IF(AND(I125>=120,I125<=155),"OK",IF(I125<120,"Corta","Larga")) -> OK | K125: Máquina de Croissants Vacíos Croistar 5000 Alba – equipo industrial para la industria de alimentos
A126: maquina-de-croissants-vacios-tkc-12-000-alba | B126: Alba | C126: Máquina de croissants vacíos TKC 12.000 Alba | D126: Máquina de Croissants Vacíos TKC 12.000 Alba | E126: Máquina de Croissants Vacíos TKC 12.000 Alba | Technofood | F126: =LEN(E126) -> 57 | G126: =IF(F126<=60,"OK","Largo") -> OK | H126: Máquina de Croissants Vacíos TKC 12.000 Alba: equipo industrial. Distribuidor autorizado en Colombia. Solicite su cotización con un asesor de Technofood. | I126: =LEN(H126) -> 153 | J126: =IF(AND(I126>=120,I126<=155),"OK",IF(I126<120,"Corta","Larga")) -> OK | K126: Máquina de Croissants Vacíos TKC 12.000 Alba – equipo industrial para la industria de alimentos
A127: divisora-boleadora-daky11 | B127: Dams | C127: Divisora boleadora DAKY11 | D127: Divisora Boleadora DAKY11 Dams | E127: Divisora Boleadora DAKY11 Dams | Technofood Colombia | F127: =LEN(E127) -> 52 | G127: =IF(F127<=60,"OK","Largo") -> OK | H127: Divisora Boleadora DAKY11 Dams: equipo industrial. Distribuidor autorizado en Colombia. Solicite su cotización con un asesor de Technofood. | I127: =LEN(H127) -> 139 | J127: =IF(AND(I127>=120,I127<=155),"OK",IF(I127<120,"Corta","Larga")) -> OK | K127: Divisora Boleadora DAKY11 Dams – equipo industrial para la industria de alimentos | L127: Se agregó la marca al título (no la tenía).
A128: divisora-boleadora-duky-54 | B128: Dams | C128: Divisora boleadora DUKY 54 | D128: Divisora Boleadora DUKY 54 Dams | E128: Divisora Boleadora DUKY 54 Dams | Technofood Colombia | F128: =LEN(E128) -> 53 | G128: =IF(F128<=60,"OK","Largo") -> OK | H128: Divisora Boleadora DUKY 54 Dams: equipo industrial. Distribuidor autorizado en Colombia. Solicite su cotización con un asesor de Technofood. | I128: =LEN(H128) -> 140 | J128: =IF(AND(I128>=120,I128<=155),"OK",IF(I128<120,"Corta","Larga")) -> OK | K128: Divisora Boleadora DUKY 54 Dams – equipo industrial para la industria de alimentos | L128: Se agregó la marca al título (no la tenía).
A129: divisora-boleadora-con-4-salidas-ddky-70 | B129: Dams | C129: Divisora boleadora con 4 salidas DDKY-70 | D129: Divisora Boleadora con 4 Salidas DDKY-70 Dams | E129: Divisora Boleadora con 4 Salidas DDKY-70 Dams | Technofood | F129: =LEN(E129) -> 58 | G129: =IF(F129<=60,"OK","Largo") -> OK | H129: Divisora Boleadora con 4 Salidas DDKY-70 Dams: equipo industrial. Distribuidor autorizado en Colombia. Solicite su cotización con un asesor de Technofood. | I129: =LEN(H129) -> 154 | J129: =IF(AND(I129>=120,I129<=155),"OK",IF(I129<120,"Corta","Larga")) -> OK | K129: Divisora Boleadora con 4 Salidas DDKY-70 Dams – equipo industrial para la industria de alimentos | L129: Se agregó la marca al título (no la tenía).
A130: divisora-boleadora-con-8-salidas-dsky-15 | B130: Dams | C130: Divisora boleadora con 8 salidas DSKY-15 | D130: Divisora Boleadora con 8 Salidas DSKY-15 Dams | E130: Divisora Boleadora con 8 Salidas DSKY-15 Dams | Technofood | F130: =LEN(E130) -> 58 | G130: =IF(F130<=60,"OK","Largo") -> OK | H130: Divisora Boleadora con 8 Salidas DSKY-15 Dams: equipo industrial. Distribuidor autorizado en Colombia. Solicite su cotización con un asesor de Technofood. | I130: =LEN(H130) -> 154 | J130: =IF(AND(I130>=120,I130<=155),"OK",IF(I130<120,"Corta","Larga")) -> OK | K130: Divisora Boleadora con 8 Salidas DSKY-15 Dams – equipo industrial para la industria de alimentos | L130: Se agregó la marca al título (no la tenía).
A131: cortadora-horizontal-bdp-xd | B131: Dovaina | C131: Cortadora horizontal BDP XD | D131: Cortadora Horizontal BDP XD Dovaina | E131: Cortadora Horizontal BDP XD Dovaina | Technofood Colombia | F131: =LEN(E131) -> 57 | G131: =IF(F131<=60,"OK","Largo") -> OK | H131: Cortadora Horizontal BDP XD Dovaina: equipo industrial. Distribuidor autorizado en Colombia. Solicite su cotización con un asesor de Technofood. | I131: =LEN(H131) -> 144 | J131: =IF(AND(I131>=120,I131<=155),"OK",IF(I131<120,"Corta","Larga")) -> OK | K131: Cortadora Horizontal BDP XD Dovaina – equipo industrial para la industria de alimentos | L131: Se agregó la marca al título (no la tenía).
...

Sheet Colecciones
A1: Handle | B1: Título actual | C1: Productos | D1: Tipo | E1: Prioridad | F1: Acción recomendada | G1: SEO title propuesto | H1: Largo title | I1: Estado title (≤60) | J1: Meta description propuesta | K1: Largo meta | L1: Estado meta (120–155) | M1: Imagen / descripción hoy
A2: frontpage | B2: Home page | C2: 0 | D2: Técnica / demo | E2: Baja | F2: Dejar sin enlazar (colección técnica de Shopify) y noindex | G2: Home page | Equipos industriales en Colombia – Technofood | H2: =LEN(G2) -> 57 | I2: =IF(H2<=60,"OK","Largo") -> OK | J2: Home page: equipos industriales para alimentos. Distribuidor autorizado en Colombia. Consulte el catálogo y cotice con Technofood. | K2: =LEN(J2) -> 130 | L2: =IF(AND(K2>=120,K2<=155),"OK",IF(K2<120,"Corta","Larga")) -> OK | M2: Sin imagen ni descripción
A3: mas-vendidos | B3: Los más vendidos | C3: 5 | D3: Técnica / demo | E3: Media | F3: Revisar: depende de tags que hoy solo tienen productos demo archivados | G3: Los más vendidos | Technofood Colombia | H3: =LEN(G3) -> 38 | I3: =IF(H3<=60,"OK","Largo") -> OK | J3: Los más vendidos: equipos industriales para alimentos. Distribuidor autorizado en Colombia. Consulte el catálogo y cotice con Technofood. | K3: =LEN(J3) -> 137 | L3: =IF(AND(K3>=120,K3<=155),"OK",IF(K3<120,"Corta","Larga")) -> OK | M3: Sin imagen ni descripción
A4: porcino | B4: Porcino | C4: 16 | D4: Industria | E4: Alta | F4: Mantener y reescribir: comparten marcas, diferenciar título y texto por industria | G4: Equipos para la industria porcina | Technofood Colombia | H4: =LEN(G4) -> 55 | I4: =IF(H4<=60,"OK","Largo") -> OK | J4: Maquinaria para plantas de proceso porcino de marcas como Taesa, Lima, Maku, Holac y Grasselli. Distribuidor autorizado en Colombia. Cotice con Technofood. | K4: =LEN(J4) -> 155 | L4: =IF(AND(K4>=120,K4<=155),"OK",IF(K4<120,"Corta","Larga")) -> OK | M4: Sin imagen ni descripción
A5: bovino | B5: Bovino | C5: 11 | D5: Industria | E5: Alta | F5: Mantener y reescribir: comparten marcas, diferenciar título y texto por industria | G5: Equipos para la industria bovina | Technofood Colombia | H5: =LEN(G5) -> 54 | I5: =IF(H5<=60,"OK","Largo") -> OK | J5: Maquinaria para plantas de proceso bovino de marcas como Taesa, Lima, Maku, Holac y Grasselli. Distribuidor autorizado en Colombia. Cotice con Technofood. | K5: =LEN(J5) -> 154 | L5: =IF(AND(K5>=120,K5<=155),"OK",IF(K5<120,"Corta","Larga")) -> OK | M5: Sin imagen ni descripción
A6: avicola | B6: Avícola | C6: 16 | D6: Industria | E6: Alta | F6: Mantener y reescribir: comparten marcas, diferenciar título y texto por industria | G6: Equipos para la industria avícola | Technofood Colombia | H6: =LEN(G6) -> 55 | I6: =IF(H6<=60,"OK","Largo") -> OK | J6: Maquinaria para plantas de proceso avícola de marcas como Baader, Lima, Bettcher y Maku. Distribuidor autorizado en Colombia. Cotice con Technofood. | K6: =LEN(J6) -> 148 | L6: =IF(AND(K6>=120,K6<=155),"OK",IF(K6<120,"Corta","Larga")) -> OK | M6: Tiene 'Texto H2 prueba' como descripción: reemplazar
A7: piscicola | B7: Piscícola | C7: 13 | D7: Industria | E7: Alta | F7: Mantener y reescribir: comparten marcas, diferenciar título y texto por industria | G7: Equipos para la industria piscícola | Technofood Colombia | H7: =LEN(G7) -> 57 | I7: =IF(H7<=60,"OK","Largo") -> OK | J7: Maquinaria para plantas de proceso piscícola de marcas como Baader, Lima, Bettcher y Maku. Distribuidor autorizado en Colombia. Cotice con Technofood. | K7: =LEN(J7) -> 150 | L7: =IF(AND(K7>=120,K7<=155),"OK",IF(K7<120,"Corta","Larga")) -> OK | M7: Sin imagen ni descripción
A8: panaderia | B8: Panadería | C8: 130 | D8: Línea / sector | E8: Alta | F8: Definir cuál es la canónica ('Panadería' 130 vs 'Línea Panadería' 121) y redirigir la otra | G8: Maquinaria para panadería en Colombia | Technofood | H8: =LEN(G8) -> 50 | I8: =IF(H8<=60,"OK","Largo") -> OK | J8: Hornos, amasadoras, divisoras, laminadoras y más para panaderías y pastelerías. Distribuidor autorizado en Colombia. Cotice con Technofood. | K8: =LEN(J8) -> 139 | L8: =IF(AND(K8>=120,K8<=155),"OK",IF(K8<120,"Corta","Larga")) -> OK | M8: Sin imagen ni descripción
A9: soluciones-destacadas | B9: Soluciones destacadas | C9: 2 | D9: Técnica / demo | E9: Media | F9: Revisar: depende de tags que hoy solo tienen productos demo archivados | G9: Soluciones destacadas | Technofood Colombia | H9: =LEN(G9) -> 43 | I9: =IF(H9<=60,"OK","Largo") -> OK | J9: Soluciones destacadas: equipos industriales para alimentos. Distribuidor autorizado en Colombia. Consulte el catálogo y cotice con Technofood. | K9: =LEN(J9) -> 142 | L9: =IF(AND(K9>=120,K9<=155),"OK",IF(K9<120,"Corta","Larga")) -> OK | M9: Sin imagen ni descripción
A10: linea-carnica | B10: Línea Cárnica | C10: 105 | D10: Línea / sector | E10: Alta | F10: Mantener y optimizar (texto introductorio + preguntas frecuentes) | G10: Maquinaria para industria cárnica en Colombia | Technofood | H10: =LEN(G10) -> 58 | I10: =IF(H10<=60,"OK","Largo") -> OK | J10: Equipos para beneficio, corte, valor agregado, empaque e higiene en la industria cárnica. Distribuidor autorizado en Colombia. Cotice con Technofood. | K10: =LEN(J10) -> 149 | L10: =IF(AND(K10>=120,K10<=155),"OK",IF(K10<120,"Corta","Larga")) -> OK | M10: Sin imagen ni descripción
A11: insumos-carnicos | B11: Insumos Cárnicos | C11: 8 | D11: Línea / sector | E11: Alta | F11: Mantener y optimizar (texto introductorio + preguntas frecuentes) | G11: Insumos para la industria cárnica | Technofood Colombia | H11: =LEN(G11) -> 55 | I11: =IF(H11<=60,"OK","Largo") -> OK | J11: Clips, lazos, tintas y consumibles para su línea cárnica. Distribuidor autorizado en Colombia. Consulte las referencias y cotice con Technofood. | K11: =LEN(J11) -> 144 | L11: =IF(AND(K11>=120,K11<=155),"OK",IF(K11<120,"Corta","Larga")) -> OK | M11: Sin imagen ni descripción
A12: insumos-panaderia | B12: Insumos Panadería | C12: 11 | D12: Línea / sector | E12: Alta | F12: Mantener y optimizar (texto introductorio + preguntas frecuentes) | G12: Insumos para panadería | Technofood Colombia | H12: =LEN(G12) -> 44 | I12: =IF(H12<=60,"OK","Largo") -> OK | J12: Agentes desmoldantes, pulverizadores, bandejas y consumibles para panadería. Distribuidor autorizado en Colombia. Cotice con Technofood. | K12: =LEN(J12) -> 136 | L12: =IF(AND(K12>=120,K12<=155),"OK",IF(K12<120,"Corta","Larga")) -> OK | M12: Sin imagen ni descripción
A13: quesos | B13: Quesos | C13: 3 | D13: Línea / sector | E13: Alta | F13: Mantener y optimizar texto | G13: Equipos para procesar quesos | Technofood Colombia | H13: =LEN(G13) -> 50 | I13: =IF(H13<=60,"OK","Largo") -> OK | J13: Cortadoras y equipos para la industria de quesos. Distribuidor autorizado en Colombia. Consulte el catálogo y cotice con un asesor de Technofood. | K13: =LEN(J13) -> 145 | L13: =IF(AND(K13>=120,K13<=155),"OK",IF(K13<120,"Corta","Larga")) -> OK | M13: Sin imagen ni descripción
... A119: technofood-insumos-panaderia | B119: Technofood · Insumos Panadería | C119: 4 | D119: Marca · insumos panadería | E119: Media | F119: Mantener: clave para búsquedas '[marca] Colombia'; enriquecer texto | G119: Technofood: insumos para panadería | Technofood | H119: =LEN(G119) -> 47 | I119: =IF(H119<=60,"OK","Largo") -> OK | J119: Insumos Technofood para panadería. Distribuidor autorizado en Colombia. Consulte las referencias disponibles y cotice con Technofood. | K119: =LEN(J119) -> 133 | L119: =IF(AND(K119>=120,K119<=155),"OK",IF(K119<120,"Corta","Larga")) -> OK | M119: Sin imagen ni descripción

Sheet Textos categorías
A1: Colección | B1: Handle | C1: H1 sugerido | D1: Texto introductorio (borrador) | E1: Palabras | F1: Pregunta frecuente | G1: Respuesta
A2: Línea Cárnica | B2: linea-carnica | C2: Maquinaria y equipos para la industria cárnica | D2: Technofood distribuye en Colombia equipos para cada etapa del proceso cárnico: beneficio, corte y acondicionamiento, valor agregado, empaque e higiene. Encuentre maquinaria de marcas como Baader, Bettcher, Efa, Frey, Seydelmann y Variovac, con asesoría para elegir el equipo según su planta. | E2: =LEN(TRIM(D2))-LEN(SUBSTITUTE(TRIM(D2)," ",""))+1 -> 41 | F2: ¿Cómo elijo la maquinaria para mi planta cárnica? | G2: Depende del tipo de proteína, el volumen de producción y la etapa del proceso. Un asesor de Technofood puede ayudarle a definir el equipo adecuado: solicite una cotización.
A3: Línea Panadería | B3: linea-panaderia | C3: Maquinaria para panaderías y pastelerías | D3: Hornos, amasadoras, divisoras, laminadoras, cámaras de fermentación y más para panaderías, pastelerías y plantas de pan. Technofood representa marcas como Logiudice, Rollmatic, Inoxforni, Ferneto y Mimac y lo acompaña en la selección del equipo. | E3: =LEN(TRIM(D3))-LEN(SUBSTITUTE(TRIM(D3)," ",""))+1 -> 34 | F3: ¿Qué equipos necesito para montar una panadería industrial? | G3: Lo básico suele incluir amasado, división y formado, fermentación y horneado, pero depende de su producción y productos. Un asesor de Technofood lo orienta.
A4: Insumos Cárnicos | B4: insumos-carnicos | C4: Insumos y consumibles para la industria cárnica | D4: Clips, lazos, cartuchos de tinta, repuestos de desplume y otros consumibles para mantener su línea cárnica en operación. Consulte las referencias disponibles y cotice con un asesor de Technofood. | E4: =LEN(TRIM(D4))-LEN(SUBSTITUTE(TRIM(D4)," ",""))+1 -> 29 | F4: ¿Cómo sé qué insumo es compatible con mi máquina? | G4: Indíquenos la marca y el modelo de su equipo y un asesor de Technofood le confirma la referencia adecuada.
A5: Insumos Panadería | B5: insumos-panaderia | C5: Insumos y consumibles para panadería | D5: Agentes desmoldantes y abrillantadores, pulverizadores, bandejas de aluminio, carretes de atar y cuchillas para rebanar pan. Cotice con un asesor de Technofood. | E5: =LEN(TRIM(D5))-LEN(SUBSTITUTE(TRIM(D5)," ",""))+1 -> 22 | F5: ¿Puedo pedir insumos junto con mi equipo? | G5: Sí. Indique en la cotización los insumos que necesita y un asesor de Technofood los incluye en la propuesta.
A6: Hornos | B6: hornos | C6: Hornos industriales para panadería y proceso cárnico | D6: Hornos rotativos, de túnel, de convección y para proceso cárnico de marcas como Logiudice, Inoxforni, Mecateck, Zanolli, Reich y Technofood. Cuéntenos su producción diaria y un asesor le recomienda el modelo. | E6: =LEN(TRIM(D6))-LEN(SUBSTITUTE(TRIM(D6)," ",""))+1 -> 31 | F6: ¿Qué horno industrial necesito para mi panadería? | G6: Depende de la producción diaria, el tipo de producto y el espacio disponible. Un asesor de Technofood puede dimensionar el equipo con usted.
A7: Amasadoras | B7: amasadoras | C7: Amasadoras industriales | D7: Amasadoras de espiral y de otros tipos de marcas como Logiudice, Inoxforni, Zanolli y Memak para panaderías y plantas de pan. Compare modelos y solicite su cotización. | E7: =LEN(TRIM(D7))-LEN(SUBSTITUTE(TRIM(D7)," ",""))+1 -> 27 | F7: ¿Cómo elijo la capacidad de una amasadora? | G7: Se define por la cantidad de masa por lote y el tipo de producto. Un asesor de Technofood le ayuda a elegir el tamaño adecuado.
A8: Divisoras y boleadoras | B8: divisoras-y-boleadoras | C8: Divisoras y boleadoras de masa | D8: Divisoras, boleadoras y redondeadores de marcas como Dams, Rollmatic, Sartori, Ferneto, Memak y Matas. Cotice el equipo según su volumen de producción. | E8: =LEN(TRIM(D8))-LEN(SUBSTITUTE(TRIM(D8)," ",""))+1 -> 22 | F8: ¿Qué diferencia hay entre una divisora y una boleadora? | G8: La divisora porciona la masa en piezas del peso deseado y la boleadora les da forma redonda. Algunos equipos hacen ambas funciones.
A9: Laminadoras | B9: laminadoras | C9: Laminadoras de masa | D9: Laminadoras manuales, compactas, semiautomáticas y automáticas de marcas como Rollmatic y Ferneto para panadería y pastelería. Consulte los modelos y cotice. | E9: =LEN(TRIM(D9))-LEN(SUBSTITUTE(TRIM(D9)," ",""))+1 -> 21 | F9: ¿Qué laminadora es adecuada para mi producción? | G9: Depende del tipo de masa, el volumen y el espacio. Un asesor de Technofood puede recomendarle el modelo.
A10: Cámaras de fermentación | B10: camaras-de-fermentacion | C10: Cámaras de fermentación industriales | D10: Cámaras de fermentación y de reposo de marcas como Logiudice, Ferneto, Inoxforni y Technofood. Cotice según su capacidad y número de carros. | E10: =LEN(TRIM(D10))-LEN(SUBSTITUTE(TRIM(D10)," ",""))+1 -> 22 | F10: ¿Cómo dimensiono una cámara de fermentación? | G10: Se define por la cantidad de producto y el número de carros o bandejas. Un asesor de Technofood le ayuda a calcularlo.
A11: Corte y fileteado | B11: corte-y-fileteado | C11: Equipos de corte y fileteado | D11: Sierras, fileteadoras, descortezadoras y rebanadoras de marcas como Efa, Grasselli, Holac y Technofood para el procesamiento cárnico. Cotice con un asesor. | E11: =LEN(TRIM(D11))-LEN(SUBSTITUTE(TRIM(D11)," ",""))+1 -> 21 | F11: ¿Qué equipo de corte necesito para mi línea? | G11: Depende del producto (carne, hueso, queso) y del tipo de corte. Un asesor de Technofood le ayuda a elegir.
A12: Inyección y marinado | B12: inyeccion-y-marinado | C12: Inyectoras, tumblers y masajeadoras | D12: Inyectoras de salmuera, tumblers, mezcladoras de salmuera y masajeadoras al vacío de marcas como Maku y Technofood para la industria cárnica. Solicite su cotización. | E12: =LEN(TRIM(D12))-LEN(SUBSTITUTE(TRIM(D12)," ",""))+1 -> 24 | F12: ¿Cuál es la diferencia entre un tumbler y una masajeadora? | G12: Ambos trabajan la carne mediante movimiento para mejorar la absorción de salmuera. El modelo adecuado depende del producto y el volumen; un asesor le orienta.
A13: Molienda y mezclado | B13: molienda-y-mezclado | C13: Molinos, mezcladoras y cutters | D13: Molinos de carne, mezcladoras, cutters y emulsificadoras de marcas como Seydelmann, Oestergaard y Technofood. Cotice el equipo para su planta. | E13: =LEN(TRIM(D13))-LEN(SUBSTITUTE(TRIM(D13)," ",""))+1 -> 20 | F13: ¿Qué equipo necesito para moler y mezclar carne? | G13: Depende del producto final y el volumen. Un asesor de Technofood le recomienda la combinación de equipos adecuada.
... A21: Piscícola | B21: piscicola | C21: Equipos para la industria piscícola | D21: Maquinaria para plantas de proceso piscícola: Baader, Lima, Bettcher, Maku, Gaser, Variovac y Technofood. Consulte el catálogo y cotice. | E21: =LEN(TRIM(D21))-LEN(SUBSTITUTE(TRIM(D21)," ",""))+1 -> 19 | F21: ¿Qué equipos necesita una planta piscícola? | G21: Depende de la etapa del proceso y del volumen. Un asesor de Technofood le ayuda a definirlos.

Sheet Palabras clave
A1: Handle de la colección | B1: Colección | C1: Palabra clave principal (propuesta) | D1: Secundarias (propuestas) | E1: Intención | F1: Prioridad
A2: hornos | B2: Hornos | C2: hornos industriales para panadería | D2: horno rotativo industrial; horno de túnel; hornos para panadería Colombia | E2: Comercial / transaccional | F2: Alta
A3: amasadoras | B3: Amasadoras | C3: amasadora industrial | D3: amasadora de espiral; amasadora para panadería; amasadora industrial Colombia | E3: Comercial / transaccional | F3: Alta
A4: divisoras-y-boleadoras | B4: Divisoras y boleadoras | C4: divisora boleadora | D4: divisora de masa; boleadora cónica; divisora de masa industrial | E4: Comercial / transaccional | F4: Alta
A5: laminadoras | B5: Laminadoras | C5: laminadora de masa industrial | D5: laminadora para panadería; laminadora automática | E5: Comercial / transaccional | F5: Media
A6: camaras-de-fermentacion | B6: Cámaras de fermentación | C6: cámara de fermentación industrial | D6: cámara de fermentación para panadería; cámara de fermentación para carros | E6: Comercial / transaccional | F6: Media
A7: corte-y-fileteado | B7: Corte y fileteado | C7: sierra para carne industrial | D7: fileteadora de carne; máquina descortezadora; rebanadora industrial | E7: Comercial / transaccional | F7: Alta
A8: inyeccion-y-marinado | B8: Inyección y marinado | C8: inyectora de salmuera | D8: tumbler al vacío; masajeadora de carne al vacío | E8: Comercial / transaccional | F8: Alta
A9: molienda-y-mezclado | B9: Molienda y mezclado | C9: molino de carne industrial | D9: mezcladora de carne; cutter industrial; emulsificadora | E9: Comercial / transaccional | F9: Alta
A10: embutido-y-porcionado | B10: Embutido y porcionado | C10: embutidora al vacío | D10: clipadora; máquina para embutidos; dosificador de embutidos | E10: Comercial / transaccional | F10: Media
A11: empaque-y-envasado | B11: Empaque y envasado | C11: máquina de envasado al vacío | D11: termoformadora; empacadora flow pack; termoselladora de bandejas | E11: Comercial / transaccional | F11: Alta
A12: higiene-y-sanitizacion-industrial | B12: Higiene y sanitización industrial | C12: lavabo industrial para plantas de alimentos | D12: limpiador de suelas industrial; estación de higiene de manos; lavadora de calzado | E12: Comercial / transaccional | F12: Media
... A16: quesos | B16: Quesos | C16: máquina para cortar queso industrial | D16: cortadora de queso; cubicadora de queso | E16: Comercial / transaccional | F16: Media
A18: Nota: son propuestas cualitativas. No se incluyó volumen de búsqueda porque no hay acceso a Search Console ni a Semrush; validar antes de priorizar.

Sheet Importar a Shopify
A1: Handle | B1: Title | C1: SEO Title | D1: SEO Description
A2: =Productos!A2 -> horno-tipo-batch-mwb2260r-440-75 | B2: =Productos!D2 -> Horno Tipo Batch MWB2260R-440-75 Amtek | C2: =Productos!E2 -> Horno Tipo Batch MWB2260R-440-75 Amtek | Technofood Colombia | D2: =Productos!H2 -> Horno Tipo Batch MWB2260R-440-75 Amtek: equipo industrial. Distribuidor autorizado en Colombia. Solicite su cotización con un asesor de Technofood.
A3: =Productos!A3 -> agente-abrillantador-backglanz-fix-fertig-100-vegetal | B3: =Productos!D3 -> Agente Abrillantador BackGlanz Fix & Fertig (100% Vegetal) Boyens | C3: =Productos!E3 -> Agente Abrillantador BackGlanz Fix & Fertig | Boyens | D3: =Productos!H3 -> Agente Abrillantador BackGlanz Fix & Fertig Boyens. Distribuidor autorizado en Colombia. Solicite su cotización con Technofood.
A4: =Productos!A4 -> cortadora-cws-300 | B4: =Productos!D4 -> Cortadora CWS 300 Grasselli | C4: =Productos!E4 -> Cortadora CWS 300 Grasselli | Technofood Colombia | D4: =Productos!H4 -> Cortadora CWS 300 Grasselli: equipo industrial para la industria de alimentos. Distribuidor autorizado en Colombia. Solicite su cotización con Technofood.
A5: =Productos!A5 -> sistema-de-temperado-amt4412r-440-2x74 | B5: =Productos!D5 -> Sistema de Temperado AMT4412R-440-2X74 Amtek | C5: =Productos!E5 -> Sistema de Temperado AMT4412R-440-2X74 Amtek | Technofood | D5: =Productos!H5 -> Sistema de Temperado AMT4412R-440-2X74 Amtek: equipo industrial. Distribuidor autorizado en Colombia. Solicite su cotización con un asesor de Technofood.
A6: =Productos!A6 -> sistema-de-temperado-amt4412r-440-75 | B6: =Productos!D6 -> Sistema de Temperado AMT4412R-440-75 Amtek | C6: =Productos!E6 -> Sistema de Temperado AMT4412R-440-75 Amtek | Technofood | D6: =Productos!H6 -> Sistema de Temperado AMT4412R-440-75 Amtek: equipo industrial. Distribuidor autorizado en Colombia. Solicite su cotización con un asesor de Technofood.
A7: =Productos!A7 -> arandela-compacta-para-suela-y-empeines-550402m | B7: =Productos!D7 -> Arandela Compacta para Suela y Empeines 550402M AWE | C7: =Productos!E7 -> Arandela Compacta para Suela y Empeines 550402M AWE | D7: =Productos!H7 -> Arandela Compacta para Suela y Empeines 550402M AWE. Distribuidor autorizado en Colombia. Solicite su cotización con Technofood.
A8: =Productos!A8 -> dispositivo-movil-de-desinfeccion-de-manos-spraybox-551801-nm | B8: =Productos!D8 -> Dispositivo Móvil de Desinfección de Manos Spraybox 551801 NM AWE | C8: =Productos!E8 -> Desinfección de Manos Spraybox 551801 NM | AWE | D8: =Productos!H8 -> Dispositivo de Desinfección de Manos Spraybox 551801 NM AWE. Distribuidor autorizado en Colombia. Solicite su cotización con Technofood.
A9: =Productos!A9 -> dispositivo-para-lavado-y-desinfeccion-de-manos-551301 | B9: =Productos!D9 -> Dispositivo para Lavado y Desinfección de Manos 551301 AWE | C9: =Productos!E9 -> Dispositivo para Lavado y Desinfección de Manos 551301 AWE | D9: =Productos!H9 -> Dispositivo para Lavado y Desinfección de Manos 551301 AWE. Distribuidor autorizado en Colombia. Solicite su cotización con Technofood.
A10: =Productos!A10 -> estacion-de-acceso-para-higiene-de-manos-cleangate-551404 | B10: =Productos!D10 -> Estación de Acceso para Higiene de Manos Cleangate 551404 AWE | C10: =Productos!E10 -> Estación Higiene de Manos Cleangate 551404 | AWE | D10: =Productos!H10 -> Estación de Higiene de Manos Cleangate 551404 AWE. Distribuidor autorizado en Colombia. Solicite su cotización con Technofood.
A11: =Productos!A11 -> lavabo-higienico-con-secador-de-manos-tip-531201 | B11: =Productos!D11 -> Lavabo Higiénico con Secador de Manos TIP 531201 AWE | C11: =Productos!E11 -> Lavabo Higiénico con Secador de Manos TIP 531201 AWE | D11: =Productos!H11 -> Lavabo Higiénico con Secador de Manos TIP 531201 AWE. Distribuidor autorizado en Colombia. Solicite su cotización con Technofood.
A12: =Productos!A12 -> lavabo-higienico-mural-kleanox-531001b | B12: =Productos!D12 -> Lavabo Higiénico Mural Kleanox 531001B AWE | C12: =Productos!E12 -> Lavabo Higiénico Mural Kleanox 531001B AWE | Technofood | D12: =Productos!H12 -> Lavabo Higiénico Mural Kleanox 531001B AWE: equipo industrial. Distribuidor autorizado en Colombia. Solicite su cotización con un asesor de Technofood.
A13: =Productos!A13 -> lavadora-de-calzado-manual-scrubo-pro-550102 | B13: =Productos!D13 -> Lavadora de Calzado Manual Scrubo Pro 550102 AWE | C13: =Productos!E13 -> Lavadora de Calzado Manual Scrubo Pro 550102 AWE | D13: =Productos!H13 -> Lavadora de Calzado Manual Scrubo Pro 550102 AWE. Distribuidor autorizado en Colombia. Solicite su cotización con Technofood.
... A243: =Productos!A243 -> linea-completa-de-envase-al-vacio-retractilado-frio-y-secado | B243: =Productos!D243 -> Línea Completa de Envase al Vacío, Retractilado, Frío y Secado Supervac | C243: =Productos!E243 -> Línea de Envase al Vacío y Retractilado | Supervac | D243: =Productos!H243 -> Línea Completa de Envase al Vacío y Retractilado Supervac. Distribuidor autorizado en Colombia. Solicite su cotización con Technofood.
